Workbook

Sheet WBS
A1: ID | B1: Entregable / Historia | C1: Tipo (feature/bug/tech) | D1: Responsable | E1: Inicio plan | F1: Fin plan | G1: BAC (presupuesto $) | H1: Costo hora ($) | I1: Horas plan | J1: Horas reales | K1: Otros costos reales ($) | L1: Regla de ganancia (EV) | M1: Estado (NI/EP/H) | N1: % completado (0-100) | O1: DoD: ítems totales | P1: DoD: ítems ok | Q1: PV al corte ($) | R1: EV ($) | S1: AC ($) | T1: SV ($) | U1: CV ($) | V1: Notas | W1: PV acumulado | X1: EV acumulado | Y1: AC acumulado
A2: 1 | B2: Evaluar precisión y relevancia de las respuestas RAG | C2: feature | D2: Alex García Castañeda | E2: 45951 | F2: 45972 | G2: 400 | H2: 40 | I2: 10 | J2: 9 | K2: 0 | L2: 50/50 | M2: H | N2: 100 | O2: 0 | P2: 0 | Q2: =IF(F2<=Costos!$B$2, G2, 0) -> 400 | R2: =IF(L2="0/100", IF(N2=100, G2, 0), IF(L2="50/50", IF(M2="H", G2, IF(M2="EP", G2*0.5, 0)), IF(L2="20/80", IF(M2="H", G2, IF(M2="EP", G2*0.2, 0)), IF(L2="Por checklist", IF(P2>0, G2*(O2/P2), G2*(N2/100)), G2*(N2/100))))) -> 400 | S2: =IFERROR(J2*H2,0)+IFERROR(K2,0) -> 360 | T2: =R2-Q2 -> 0 | U2: =R2-S2 -> 40 | W2: =IFERROR(Q2,0) -> 400 | X2: =IFERROR(R2,0) -> 400 | Y2: =IFERROR(S2,0) -> 360
A3: 2 | B3: Diseñar estructura de memoria contextual | C3: tech | D3: Alex García Castañeda | E3: 45951 | F3: 45973 | G3: 420 | H3: 42 | I3: 10 | J3: 9 | K3: 0 | L3: 50/50 | M3: H | N3: 100 | O3: 0 | P3: 0 | Q3: =IF(F3<=Costos!$B$2, G3, 0) -> 420 | R3: =IF(L3="0/100", IF(N3=100, G3, 0), IF(L3="50/50", IF(M3="H", G3, IF(M3="EP", G3*0.5, 0)), IF(L3="20/80", IF(M3="H", G3, IF(M3="EP", G3*0.2, 0)), IF(L3="Por checklist", IF(P3>0, G3*(O3/P3), G3*(N3/100)), G3*(N3/100))))) -> 420 | S3: =IFERROR(J3*H3,0)+IFERROR(K3,0) -> 378 | T3: =R3-Q3 -> 0 | U3: =R3-S3 -> 42 | W3: =IFERROR(W2+Q3, W2) -> 820 | X3: =IFERROR(X2+R3, X2) -> 820 | Y3: =IFERROR(Y2+S3, Y2) -> 738
A4: 3 | B4: Consultar historial conversacional por usuario y fecha | C4: feature | D4: Alex García Castañeda | E4: 45951 | F4: 45974 | G4: 480 | H4: 40 | I4: 12 | J4: 12 | K4: 0 | L4: 50/50 | M4: H | N4: 100 | O4: 0 | P4: 0 | Q4: =IF(F4<=Costos!$B$2, G4, 0) -> 480 | R4: =IF(L4="0/100", IF(N4=100, G4, 0), IF(L4="50/50", IF(M4="H", G4, IF(M4="EP", G4*0.5, 0)), IF(L4="20/80", IF(M4="H", G4, IF(M4="EP", G4*0.2, 0)), IF(L4="Por checklist", IF(P4>0, G4*(O4/P4), G4*(N4/100)), G4*(N4/100))))) -> 480 | S4: =IFERROR(J4*H4,0)+IFERROR(K4,0) -> 480 | T4: =R4-Q4 -> 0 | U4: =R4-S4 -> 0 | W4: =IFERROR(W3+Q4, W3) -> 1300 | X4: =IFERROR(X3+R4, X3) -> 1300 | Y4: =IFERROR(Y3+S4, Y3) -> 1218
A5: 4 | B5: Crear endpoints REST para gestión de usuarios | C5: feature | D5: Juan Manuel Arango Rodas | E5: 45951 | F5: 45975 | G5: 560 | H5: 40 | I5: 14 | J5: 15 | K5: 0 | L5: Por checklist | M5: H | N5: 100 | O5: 6 | P5: 6 | Q5: =IF(F5<=Costos!$B$2, G5, 0) -> 560 | R5: =IF(L5="0/100", IF(N5=100, G5, 0), IF(L5="50/50", IF(M5="H", G5, IF(M5="EP", G5*0.5, 0)), IF(L5="20/80", IF(M5="H", G5, IF(M5="EP", G5*0.2, 0)), IF(L5="Por checklist", IF(P5>0, G5*(O5/P5), G5*(N5/100)), G5*(N5/100))))) -> 560 | S5: =IFERROR(J5*H5,0)+IFERROR(K5,0) -> 600 | T5: =R5-Q5 -> 0 | U5: =R5-S5 -> -40 | W5: =IFERROR(W4+Q5, W4) -> 1860 | X5: =IFERROR(X4+R5, X4) -> 1860 | Y5: =IFERROR(Y4+S5, Y4) -> 1818
A6: 5 | B6: Implementación de capa de acceso a datos (DAO / Repository) | C6: tech | D6: Tina María Torres Tascón | E6: 45951 | F6: 45976 | G6: 336 | H6: 42 | I6: 8 | J6: 7 | K6: 0 | L6: 50/50 | M6: H | N6: 100 | O6: 0 | P6: 0 | Q6: =IF(F6<=Costos!$B$2, G6, 0) -> 336 | R6: =IF(L6="0/100", IF(N6=100, G6, 0), IF(L6="50/50", IF(M6="H", G6, IF(M6="EP", G6*0.5, 0)), IF(L6="20/80", IF(M6="H", G6, IF(M6="EP", G6*0.2, 0)), IF(L6="Por checklist", IF(P6>0, G6*(O6/P6), G6*(N6/100)), G6*(N6/100))))) -> 336 | S6: =IFERROR(J6*H6,0)+IFERROR(K6,0) -> 294 | T6: =R6-Q6 -> 0 | U6: =R6-S6 -> 42 | W6: =IFERROR(W5+Q6, W5) -> 2196 | X6: =IFERROR(X5+R6, X5) -> 2196 | Y6: =IFERROR(Y5+S6, Y5) -> 2112
A7: 6 | B7: Generación y gestión de embeddings | C7: tech | D7: Alex García Castañeda | E7: 45951 | F7: 45977 | G7: 336 | H7: 42 | I7: 8 | J7: 9 | K7: 0 | L7: Por checklist | M7: H | N7: 100 | O7: 5 | P7: 5 | Q7: =IF(F7<=Costos!$B$2, G7, 0) -> 336 | R7: =IF(L7="0/100", IF(N7=100, G7, 0), IF(L7="50/50", IF(M7="H", G7, IF(M7="EP", G7*0.5, 0)), IF(L7="20/80", IF(M7="H", G7, IF(M7="EP", G7*0.2, 0)), IF(L7="Por checklist", IF(P7>0, G7*(O7/P7), G7*(N7/100)), G7*(N7/100))))) -> 336 | S7: =IFERROR(J7*H7,0)+IFERROR(K7,0) -> 378 | T7: =R7-Q7 -> 0 | U7: =R7-S7 -> -42 | W7: =IFERROR(W6+Q7, W6) -> 2532 | X7: =IFERROR(X6+R7, X6) -> 2532 | Y7: =IFERROR(Y6+S7, Y6) -> 2490
A8: 7 | B8: Configuración del entorno local con Docker | C8: feature | D8: Juan Manuel Arango Rodas | E8: 45951 | F8: 45978 | G8: 640 | H8: 40 | I8: 16 | J8: 12 | K8: 50 | L8: Por checklist | M8: H | N8: 100 | O8: 10 | P8: 7 | Q8: =IF(F8<=Costos!$B$2, G8, 0) -> 640 | R8: =IF(L8="0/100", IF(N8=100, G8, 0), IF(L8="50/50", IF(M8="H", G8, IF(M8="EP", G8*0.5, 0)), IF(L8="20/80", IF(M8="H", G8, IF(M8="EP", G8*0.2, 0)), IF(L8="Por checklist", IF(P8>0, G8*(O8/P8), G8*(N8/100)), G8*(N8/100))))) -> 914.28571 | S8: =IFERROR(J8*H8,0)+IFERROR(K8,0) -> 530 | T8: =R8-Q8 -> 274.28571 | U8: =R8-S8 -> 384.28571 | W8: =IFERROR(W7+Q8, W7) -> 3172 | X8: =IFERROR(X7+R8, X7) -> 3446.2857 | Y8: =IFERROR(Y7+S8, Y7) -> 3020
A9: 8 | B9: Definición de arquitectura lógica y técnica | C9: bug | D9: Alex García Castañeda | E9: 45951 | F9: 45979 | G9: 160 | H9: 40 | I9: 4 | J9: 5 | K9: 0 | L9: 0/100 | M9: H | N9: 100 | O9: 0 | P9: 0 | Q9: =IF(F9<=Costos!$B$2, G9, 0) -> 160 | R9: =IF(L9="0/100", IF(N9=100, G9, 0), IF(L9="50/50", IF(M9="H", G9, IF(M9="EP", G9*0.5, 0)), IF(L9="20/80", IF(M9="H", G9, IF(M9="EP", G9*0.2, 0)), IF(L9="Por checklist", IF(P9>0, G9*(O9/P9), G9*(N9/100)), G9*(N9/100))))) -> 160 | S9: =IFERROR(J9*H9,0)+IFERROR(K9,0) -> 200 | T9: =R9-Q9 -> 0 | U9: =R9-S9 -> -40 | W9: =IFERROR(W8+Q9, W8) -> 3332 | X9: =IFERROR(X8+R9, X8) -> 3606.2857 | Y9: =IFERROR(Y8+S9, Y8) -> 3220
A10: 9 | B10: Diseño del modelo de datos relacional y vectorial | C10: feature | D10: Stiven Henao Aricapa | E10: 45951 | F10: 45980 | G10: 720 | H10: 45 | I10: 16 | J10: 8 | K10: 0 | L10: 20/80 | M10: H | N10: 100 | O10: 0 | P10: 0 | Q10: =IF(F10<=Costos!$B$2, G10, 0) -> 720 | R10: =IF(L10="0/100", IF(N10=100, G10, 0), IF(L10="50/50", IF(M10="H", G10, IF(M10="EP", G10*0.5, 0)), IF(L10="20/80", IF(M10="H", G10, IF(M10="EP", G10*0.2, 0)), IF(L10="Por checklist", IF(P10>0, G10*(O10/P10), G10*(N10/100)), G10*(N10/100))))) -> 720 | S10: =IFERROR(J10*H10,0)+IFERROR(K10,0) -> 360 | T10: =R10-Q10 -> 0 | U10: =R10-S10 -> 360 | W10: =IFERROR(W9+Q10, W9) -> 4052 | X10: =IFERROR(X9+R10, X9) -> 4326.2857 | Y10: =IFERROR(Y9+S10, Y9) -> 3580
A11: 10 | B11: Configurar conexión con el modelo Gemini | C11: feature | D11: Víctor Manuel Hernández Ortíz | E11: 45951 | F11: 45981 | G11: 810 | H11: 45 | I11: 18 | J11: 10 | K11: 0 | L11: 0/100 | M11: H | N11: 100 | O11: 0 | P11: 0 | Q11: =IF(F11<=Costos!$B$2, G11, 0) -> 810 | R11: =IF(L11="0/100", IF(N11=100, G11, 0), IF(L11="50/50", IF(M11="H", G11, IF(M11="EP", G11*0.5, 0)), IF(L11="20/80", IF(M11="H", G11, IF(M11="EP", G11*0.2, 0)), IF(L11="Por checklist", IF(P11>0, G11*(O11/P11), G11*(N11/100)), G11*(N11/100))))) -> 810 | S11: =IFERROR(J11*H11,0)+IFERROR(K11,0) -> 450 | T11: =R11-Q11 -> 0 | U11: =R11-S11 -> 360 | W11: =IFERROR(W10+Q11, W10) -> 4862 | X11: =IFERROR(X10+R11, X10) -> 5136.2857 | Y11: =IFERROR(Y10+S11, Y10) -> 4030
A12: 11 | B12: Diseño del pipeline de conversación | C12: tech | D12: Stiven Henao Aricapa | E12: 45951 | F12: 45982 | G12: 480 | H12: 40 | I12: 12 | J12: 6 | K12: 0 | L12: 20/80 | M12: H | N12: 100 | O12: 0 | P12: 0 | Q12: =IF(F12<=Costos!$B$2, G12, 0) -> 480 | R12: =IF(L12="0/100", IF(N12=100, G12, 0), IF(L12="50/50", IF(M12="H", G12, IF(M12="EP", G12*0.5, 0)), IF(L12="20/80", IF(M12="H", G12, IF(M12="EP", G12*0.2, 0)), IF(L12="Por checklist", IF(P12>0, G12*(O12/P12), G12*(N12/100)), G12*(N12/100))))) -> 480 | S12: =IFERROR(J12*H12,0)+IFERROR(K12,0) -> 240 | T12: =R12-Q12 -> 0 | U12: =R12-S12 -> 240 | W12: =IFERROR(W11+Q12, W11) -> 5342 | X12: =IFERROR(X11+R12, X11) -> 5616.2857 | Y12: =IFERROR(Y11+S12, Y11) -> 4270
A13: 12 | B13: Implementar RAG básico con artículos psicológicos | C13: tech | D13: Juan Sebastían Gómez Agudelo | E13: 45951 | F13: 45983 | G13: 240 | H13: 40 | I13: 6 | J13: 0 | K13: 0 | L13: 0/100 | M13: H | N13: 100 | O13: 0 | P13: 0 | Q13: =IF(F13<=Costos!$B$2, G13, 0) -> 240 | R13: =IF(L13="0/100", IF(N13=100, G13, 0), IF(L13="50/50", IF(M13="H", G13, IF(M13="EP", G13*0.5, 0)), IF(L13="20/80", IF(M13="H", G13, IF(M13="EP", G13*0.2, 0)), IF(L13="Por checklist", IF(P13>0, G13*(O13/P13), G13*(N13/100)), G13*(N13/100))))) -> 240 | S13: =IFERROR(J13*H13,0)+IFERROR(K13,0) -> 0 | T13: =R13-Q13 -> 0 | U13: =R13-S13 -> 240 | W13: =IFERROR(W12+Q13, W12) -> 5582 | X13: =IFERROR(X12+R13, X12) -> 5856.2857 | Y13: =IFERROR(Y12+S13, Y12) -> 4270
A14: 13 | B14: Memoria contextual integrada al flujo conversacional + RAG | C14: feature | D14: Stiven Henao Aricapa | E14: 45951 | F14: 45984 | G14: 520 | H14: 40 | I14: 13 | J14: 14 | K14: 0 | L14: 50/50 | M14: H | N14: 100 | O14: 0 | P14: 0 | Q14: =IF(F14<=Costos!$B$2, G14, 0) -> 520 | R14: =IF(L14="0/100", IF(N14=100, G14, 0), IF(L14="50/50", IF(M14="H", G14, IF(M14="EP", G14*0.5, 0)), IF(L14="20/80", IF(M14="H", G14, IF(M14="EP", G14*0.2, 0)), IF(L14="Por checklist", IF(P14>0, G14*(O14/P14), G14*(N14/100)), G14*(N14/100))))) -> 520 | S14: =IFERROR(J14*H14,0)+IFERROR(K14,0) -> 560 | T14: =R14-Q14 -> 0 | U14: =R14-S14 -> -40 | W14: =IFERROR(W13+Q14, W13) -> 6102 | X14: =IFERROR(X13+R14, X13) -> 6376.2857 | Y14: =IFERROR(Y13+S14, Y13) -> 4830
... A21: 20 | B21: Pruebas finales + documentación entregable | C21: tech | D21: Tina María Torres Tascón | E21: 45992 | F21: 46006 | G21: 240 | H21: 40 | I21: 6 | J21: 5 | K21: 0 | L21: 0/100 | M21: EP | N21: 0 | O21: 0 | P21: 0 | Q21: =IF(F21<=Costos!$B$2, G21, 0) -> 0 | R21: =IF(L21="0/100", IF(N21=100, G21, 0), IF(L21="50/50", IF(M21="H", G21, IF(M21="EP", G21*0.5, 0)), IF(L21="20/80", IF(M21="H", G21, IF(M21="EP", G21*0.2, 0)), IF(L21="Por checklist", IF(P21>0, G21*(O21/P21), G21*(N21/100)), G21*(N21/100))))) -> 0 | S21: =IFERROR(J21*H21,0)+IFERROR(K21,0) -> 200 | T21: =R21-Q21 -> 0 | U21: =R21-S21 -> -200 | W21: =IFERROR(W20+Q21, W20) -> 6102 | X21: =IFERROR(X20+R21, X20) -> 6680.2857 | Y21: =IFERROR(Y20+S21, Y20) -> 6990
D22: Sebastián Gómez Agudelo | E22: 45992 | F22: 46006 | M22: NI | Q22: =IF(F22<=Costos!$B$2, G22, 0) -> 0 | R22: =IF(L22="0/100", IF(N22=100, G22, 0), IF(L22="50/50", IF(M22="H", G22, IF(M22="EP", G22*0.5, 0)), IF(L22="20/80", IF(M22="H", G22, IF(M22="EP", G22*0.2, 0)), IF(L22="Por checklist", IF(P22>0, G22*(O22/P22), G22*(N22/100)), G22*(N22/100))))) -> 0 | S22: =IFERROR(J22*H22,0)+IFERROR(K22,0) -> 0 | T22: =R22-Q22 -> 0 | U22: =R22-S22 -> 0 | W22: =IFERROR(W21+Q22, W21) -> 6102 | X22: =IFERROR(X21+R22, X21) -> 6680.2857 | Y22: =IFERROR(Y21+S22, Y21) -> 6990
M23: NI | Q23: =IF(F23<=Costos!$B$2, G23, 0) | R23: =IF(L23="0/100", IF(N23=100, G23, 0), IF(L23="50/50", IF(M23="H", G23, IF(M23="EP", G23*0.5, 0)), IF(L23="20/80", IF(M23="H", G23, IF(M23="EP", G23*0.2, 0)), IF(L23="Por checklist", IF(P23>0, G23*(O23/P23), G23*(N23/100)), G23*(N23/100))))) -> 0 | S23: =IFERROR(J23*H23,0)+IFERROR(K23,0) -> 0 | T23: =R23-Q23 -> 0 | U23: =R23-S23 -> 0 | W23: =IFERROR(W22+Q23, W22) -> 6102 | X23: =IFERROR(X22+R23, X22) -> 6680.2857 | Y23: =IFERROR(Y22+S23, Y22) -> 6990
M24: NI | Q24: =IF(F24<=Costos!$B$2, G24, 0) | R24: =IF(L24="0/100", IF(N24=100, G24, 0), IF(L24="50/50", IF(M24="H", G24, IF(M24="EP", G24*0.5, 0)), IF(L24="20/80", IF(M24="H", G24, IF(M24="EP", G24*0.2, 0)), IF(L24="Por checklist", IF(P24>0, G24*(O24/P24), G24*(N24/100)), G24*(N24/100))))) -> 0 | S24: =IFERROR(J24*H24,0)+IFERROR(K24,0) -> 0 | T24: =R24-Q24 -> 0 | U24: =R24-S24 -> 0 | W24: =IFERROR(W23+Q24, W23) -> 6102 | X24: =IFERROR(X23+R24, X23) -> 6680.2857 | Y24: =IFERROR(Y23+S24, Y23) -> 6990
M25: NI | Q25: =IF(F25<=Costos!$B$2, G25, 0) | R25: =IF(L25="0/100", IF(N25=100, G25, 0), IF(L25="50/50", IF(M25="H", G25, IF(M25="EP", G25*0.5, 0)), IF(L25="20/80", IF(M25="H", G25, IF(M25="EP", G25*0.2, 0)), IF(L25="Por checklist", IF(P25>0, G25*(O25/P25), G25*(N25/100)), G25*(N25/100))))) -> 0 | S25: =IFERROR(J25*H25,0)+IFERROR(K25,0) -> 0 | T25: =R25-Q25 -> 0 | U25: =R25-S25 -> 0 | W25: =IFERROR(W24+Q25, W24) -> 6102 | X25: =IFERROR(X24+R25, X24) -> 6680.2857 | Y25: =IFERROR(Y24+S25, Y24) -> 6990
M26: NI | Q26: =IF(F26<=Costos!$B$2, G26, 0) | R26: =IF(L26="0/100", IF(N26=100, G26, 0), IF(L26="50/50", IF(M26="H", G26, IF(M26="EP", G26*0.5, 0)), IF(L26="20/80", IF(M26="H", G26, IF(M26="EP", G26*0.2, 0)), IF(L26="Por checklist", IF(P26>0, G26*(O26/P26), G26*(N26/100)), G26*(N26/100))))) -> 0 | S26: =IFERROR(J26*H26,0)+IFERROR(K26,0) -> 0 | T26: =R26-Q26 -> 0 | U26: =R26-S26 -> 0 | W26: =IFERROR(W25+Q26, W25) -> 6102 | X26: =IFERROR(X25+R26, X25) -> 6680.2857 | Y26: =IFERROR(Y25+S26, Y25) -> 6990
M27: NI | Q27: =IF(F27<=Costos!$B$2, G27, 0) | R27: =IF(L27="0/100", IF(N27=100, G27, 0), IF(L27="50/50", IF(M27="H", G27, IF(M27="EP", G27*0.5, 0)), IF(L27="20/80", IF(M27="H", G27, IF(M27="EP", G27*0.2, 0)), IF(L27="Por checklist", IF(P27>0, G27*(O27/P27), G27*(N27/100)), G27*(N27/100))))) -> 0 | S27: =IFERROR(J27*H27,0)+IFERROR(K27,0) -> 0 | T27: =R27-Q27 -> 0 | U27: =R27-S27 -> 0 | W27: =IFERROR(W26+Q27, W26) -> 6102 | X27: =IFERROR(X26+R27, X26) -> 6680.2857 | Y27: =IFERROR(Y26+S27, Y26) -> 6990
M28: NI | Q28: =IF(F28<=Costos!$B$2, G28, 0) | R28: =IF(L28="0/100", IF(N28=100, G28, 0), IF(L28="50/50", IF(M28="H", G28, IF(M28="EP", G28*0.5, 0)), IF(L28="20/80", IF(M28="H", G28, IF(M28="EP", G28*0.2, 0)), IF(L28="Por checklist", IF(P28>0, G28*(O28/P28), G28*(N28/100)), G28*(N28/100))))) -> 0 | S28: =IFERROR(J28*H28,0)+IFERROR(K28,0) -> 0 | T28: =R28-Q28 -> 0 | U28: =R28-S28 -> 0 | W28: =IFERROR(W27+Q28, W27) -> 6102 | X28: =IFERROR(X27+R28, X27) -> 6680.2857 | Y28: =IFERROR(Y27+S28, Y27) -> 6990
M29: NI | Q29: =IF(F29<=Costos!$B$2, G29, 0) | R29: =IF(L29="0/100", IF(N29=100, G29, 0), IF(L29="50/50", IF(M29="H", G29, IF(M29="EP", G29*0.5, 0)), IF(L29="20/80", IF(M29="H", G29, IF(M29="EP", G29*0.2, 0)), IF(L29="Por checklist", IF(P29>0, G29*(O29/P29), G29*(N29/100)), G29*(N29/100))))) -> 0 | S29: =IFERROR(J29*H29,0)+IFERROR(K29,0) -> 0 | T29: =R29-Q29 -> 0 | U29: =R29-S29 -> 0 | W29: =IFERROR(W28+Q29, W28) -> 6102 | X29: =IFERROR(X28+R29, X28) -> 6680.2857 | Y29: =IFERROR(Y28+S29, Y28) -> 6990
M30: NI | Q30: =IF(F30<=Costos!$B$2, G30, 0) | R30: =IF(L30="0/100", IF(N30=100, G30, 0), IF(L30="50/50", IF(M30="H", G30, IF(M30="EP", G30*0.5, 0)), IF(L30="20/80", IF(M30="H", G30, IF(M30="EP", G30*0.2, 0)), IF(L30="Por checklist", IF(P30>0, G30*(O30/P30), G30*(N30/100)), G30*(N30/100))))) -> 0 | S30: =IFERROR(J30*H30,0)+IFERROR(K30,0) -> 0 | T30: =R30-Q30 -> 0 | U30: =R30-S30 -> 0 | W30: =IFERROR(W29+Q30, W29) -> 6102 | X30: =IFERROR(X29+R30, X29) -> 6680.2857 | Y30: =IFERROR(Y29+S30, Y29) -> 6990
M31: NI | Q31: =IF(F31<=Costos!$B$2, G31, 0) | R31: =IF(L31="0/100", IF(N31=100, G31, 0), IF(L31="50/50", IF(M31="H", G31, IF(M31="EP", G31*0.5, 0)), IF(L31="20/80", IF(M31="H", G31, IF(M31="EP", G31*0.2, 0)), IF(L31="Por checklist", IF(P31>0, G31*(O31/P31), G31*(N31/100)), G31*(N31/100))))) -> 0 | S31: =IFERROR(J31*H31,0)+IFERROR(K31,0) -> 0 | T31: =R31-Q31 -> 0 | U31: =R31-S31 -> 0 | W31: =IFERROR(W30+Q31, W30) -> 6102 | X31: =IFERROR(X30+R31, X30) -> 6680.2857 | Y31: =IFERROR(Y30+S31, Y30) -> 6990
M32: NI | Q32: =IF(F32<=Costos!$B$2, G32, 0) | R32: =IF(L32="0/100", IF(N32=100, G32, 0), IF(L32="50/50", IF(M32="H", G32, IF(M32="EP", G32*0.5, 0)), IF(L32="20/80", IF(M32="H", G32, IF(M32="EP", G32*0.2, 0)), IF(L32="Por checklist", IF(P32>0, G32*(O32/P32), G32*(N32/100)), G32*(N32/100))))) -> 0 | S32: =IFERROR(J32*H32,0)+IFERROR(K32,0) -> 0 | T32: =R32-Q32 -> 0 | U32: =R32-S32 -> 0 | W32: =IFERROR(W31+Q32, W31) -> 6102 | X32: =IFERROR(X31+R32, X31) -> 6680.2857 | Y32: =IFERROR(Y31+S32, Y31) -> 6990
M33: NI | Q33: =IF(F33<=Costos!$B$2, G33, 0) | R33: =IF(L33="0/100", IF(N33=100, G33, 0), IF(L33="50/50", IF(M33="H", G33, IF(M33="EP", G33*0.5, 0)), IF(L33="20/80", IF(M33="H", G33, IF(M33="EP", G33*0.2, 0)), IF(L33="Por checklist", IF(P33>0, G33*(O33/P33), G33*(N33/100)), G33*(N33/100))))) -> 0 | S33: =IFERROR(J33*H33,0)+IFERROR(K33,0) -> 0 | T33: =R33-Q33 -> 0 | U33: =R33-S33 -> 0 | W33: =IFERROR(W32+Q33, W32) -> 6102 | X33: =IFERROR(X32+R33, X32) -> 6680.2857 | Y33: =IFERROR(Y32+S33, Y32) -> 6990
M34: NI | Q34: =IF(F34<=Costos!$B$2, G34, 0) | R34: =IF(L34="0/100", IF(N34=100, G34, 0), IF(L34="50/50", IF(M34="H", G34, IF(M34="EP", G34*0.5, 0)), IF(L34="20/80", IF(M34="H", G34, IF(M34="EP", G34*0.2, 0)), IF(L34="Por checklist", IF(P34>0, G34*(O34/P34), G34*(N34/100)), G34*(N34/100))))) -> 0 | S34: =IFERROR(J34*H34,0)+IFERROR(K34,0) -> 0 | T34: =R34-Q34 -> 0 | U34: =R34-S34 -> 0 | W34: =IFERROR(W33+Q34, W33) -> 6102 | X34: =IFERROR(X33+R34, X33) -> 6680.2857 | Y34: =IFERROR(Y33+S34, Y33) -> 6990
... M40: NI | Q40: =IF(F40<=Costos!$B$2, G40, 0) | R40: =IF(L40="0/100", IF(N40=100, G40, 0), IF(L40="50/50", IF(M40="H", G40, IF(M40="EP", G40*0.5, 0)), IF(L40="20/80", IF(M40="H", G40, IF(M40="EP", G40*0.2, 0)), IF(L40="Por checklist", IF(P40>0, G40*(O40/P40), G40*(N40/100)), G40*(N40/100))))) -> 0 | S40: =IFERROR(J40*H40,0)+IFERROR(K40,0) -> 0 | T40: =R40-Q40 -> 0 | U40: =R40-S40 -> 0 | W40: =IFERROR(W39+Q40, W39) -> 6102 | X40: =IFERROR(X39+R40, X39) -> 6680.2857 | Y40: =IFERROR(Y39+S40, Y39) -> 6990

Sheet Costos
A1: Parámetro | B1: Valor
A2: Fecha de corte (reporte) | B2: 45989
A3: Observaciones | B3: Ajusta la fecha de corte para que PV se calcule con base en Fin plan.

Sheet Métricas
A1: Indicador | B1: Descripción | C1: Valor
A2: BAC total ($) | B2: Suma presupuestada de todos los entregables (Budget At Completion). | C2: =SUM(WBS!G2:G40) -> 8202
A3: PV total al corte ($) | B3: Valor planeado acumulado hasta la fecha de corte (sumatoria de BAC de tareas con Fin plan <= corte). | C3: =SUM(WBS!Q2:Q40) -> 6102
A4: EV total ($) | B4: Valor ganado a la fecha de corte según reglas de ganancia y DoD. | C4: =SUM(WBS!R2:R40) -> 6680.2857
A5: AC total ($) | B5: Costo real incurrido a la fecha de corte (horas reales * costo + otros). | C5: =SUM(WBS!S2:S40) -> 6990
A6: SV ($) = EV - PV | B6: Varianza de cronograma; >0 adelanto, <0 atraso. | C6: =C4-C3 -> 578.28571
A7: CV ($) = EV - AC | B7: Varianza de costos; >0 ahorro, <0 sobrecosto. | C7: =C4-C5 -> -309.71429
A8: SPI = EV / PV | B8: Índice de desempeño de cronograma; 1.0 es on-track. | C8: =IF(C3>0, C4/C3, 0) -> 1.0947699
A9: CPI = EV / AC | B9: Índice de desempeño de costos; 1.0 es on-budget. | C9: =IF(C5>0, C4/C5, 0) -> 0.9556918
A10: EAC = BAC / CPI | B10: Estimado al completar; proyección de costo final. | C10: =IF(C8>0, C2/C8, 0) -> 7491.9855
A11: ETC = EAC - AC | B11: Costo por incurrir restante. | C11: =C9-C5 -> -6989.0443
A13: Notas rápidas
A14: • Actualiza 'Fecha de corte' en Costos!B2. • Llena WBS con: BAC, fechas, regla de ganancia, DoD, horas reales y otros costos. • Estado: NI = No iniciado, EP = En progreso, H = Hecho. • Regla 'Por checklist' usa DoD: ítems ok / ítems totales. • Los indicadores se calculan automáticamente.

Sheet Gráficos
A1: Gráficos automáticos
A2: Rango de datos detectado: 2..40
A3: Curva S (PV/EV/AC acumulados)
A4: Burnup (EV acumulado vs PV acumulado + BAC)
A10: Alcance (BAC) | B10: Alcance (BAC) | C10: ='Métricas'!C2 -> 8202
B11: Alcance (BAC) | C11: ='Métricas'!C2 -> 8202
B12: Alcance (BAC) | C12: ='Métricas'!C2 -> 8202
B13: Alcance (BAC) | C13: ='Métricas'!C2 -> 8202
B14: Alcance (BAC) | C14: ='Métricas'!C2 -> 8202
B15: Alcance (BAC) | C15: ='Métricas'!C2 -> 8202
B16: Alcance (BAC) | C16: ='Métricas'!C2 -> 8202
B17: Alcance (BAC) | C17: ='Métricas'!C2 -> 8202
B18: Alcance (BAC) | C18: ='Métricas'!C2 -> 8202
B19: Alcance (BAC) | C19: ='Métricas'!C2 -> 8202
B20: Alcance (BAC) | C20: ='Métricas'!C2 -> 8202
B21: Alcance (BAC) | C21: ='Métricas'!C2 -> 8202
B22: Alcance (BAC) | C22: ='Métricas'!C2 -> 8202
B23: Alcance (BAC) | C23: ='Métricas'!C2 -> 8202
B24: Alcance (BAC) | C24: ='Métricas'!C2 -> 8202
B25: Alcance (BAC) | C25: ='Métricas'!C2 -> 8202
B26: Alcance (BAC) | C26: ='Métricas'!C2 -> 8202
B27: Alcance (BAC) | C27: ='Métricas'!C2 -> 8202
B28: Alcance (BAC) | C28: ='Métricas'!C2 -> 8202
B29: Alcance (BAC) | C29: ='Métricas'!C2 -> 8202
B30: Alcance (BAC) | C30: ='Métricas'!C2 -> 8202
B31: Alcance (BAC) | C31: ='Métricas'!C2 -> 8202
B32: Alcance (BAC) | C32: ='Métricas'!C2 -> 8202
B33: Alcance (BAC) | C33: ='Métricas'!C2 -> 8202
B34: Alcance (BAC) | C34: ='Métricas'!C2 -> 8202
B35: Alcance (BAC) | C35: ='Métricas'!C2 -> 8202
B36: Alcance (BAC) | C36: ='Métricas'!C2 -> 8202
B37: Alcance (BAC) | C37: ='Métricas'!C2 -> 8202
B38: Alcance (BAC) | C38: ='Métricas'!C2 -> 8202
B39: Alcance (BAC) | C39: ='Métricas'!C2 -> 8202
B40: Alcance (BAC) | C40: ='Métricas'!C2 -> 8202
B41: Alcance (BAC) | C41: ='Métricas'!C2 -> 8202
B42: Alcance (BAC) | C42: ='Métricas'!C2 -> 8202
B43: Alcance (BAC) | C43: ='Métricas'!C2 -> 8202
B44: Alcance (BAC) | C44: ='Métricas'!C2 -> 8202
B45: Alcance (BAC) | C45: ='Métricas'!C2 -> 8202
...

Sheet WBS (solución)
A1: Interpretación del sprint (EV, PV, AC, índices y acciones)
A2: Fecha de corte: 2025-11-28 00:00:00
A4: Resumen de indicadores (desde Métricas)
A5: BAC total ($) | B5: ='Métricas'!C2 -> 8202 | D5: Guía rápida
A6: PV total al corte ($) | B6: ='Métricas'!C3 -> 6102 | D6: SPI ~1 OK; <1 atraso.
A7: EV total ($) | B7: ='Métricas'!C4 -> 6680.2857 | D7: CPI ~1 OK; <1 sobrecosto.
A8: AC total ($) | B8: ='Métricas'!C5 -> 6990 | D8: EAC alto sugiere revisar alcance/tiempos.
A9: SPI = EV/PV | B9: ='Métricas'!C7 -> -309.71429
A10: CPI = EV/AC | B10: ='Métricas'!C8 -> 1.0947699
A11: EAC = BAC/CPI | B11: ='Métricas'!C9 -> 0.9556918
A12: ETC = EAC - AC | B12: ='Métricas'!C10 -> 7491.9855
A15: Ítems con atraso o sobrecosto
A16: ID | B16: Entregable | C16: Fin plan | D16: PV | E16: EV | F16: AC | G16: SV (EV-PV) | H16: CV (EV-AC) | I16: Acción sugerida
A17: 1 | B17: No se identifican ítems en atraso ni en sobrecosto; el desempeño del sprint es conforme al plan | D17: =WBS!Q2 -> 400 | E17: =WBS!R2 -> 400 | F17: =WBS!S2 -> 360 | G17: =E17-D17 -> 0 | H17: =E17-F17 -> 40 | I17: Si SV<0: dividir en sub-tareas o reasignar; Si CV<0: limitar horas, revisar tarifa o scope.
A18: 2 | D18: =WBS!Q3 -> 420 | E18: =WBS!R3 -> 420 | F18: =WBS!S3 -> 378 | G18: =E18-D18 -> 0 | H18: =E18-F18 -> 42 | I18: Si SV<0: dividir en sub-tareas o reasignar; Si CV<0: limitar horas, revisar tarifa o scope.
A19: 3 | D19: =WBS!Q4 -> 480 | E19: =WBS!R4 -> 480 | F19: =WBS!S4 -> 480 | G19: =E19-D19 -> 0 | H19: =E19-F19 -> 0 | I19: Si SV<0: dividir en sub-tareas o reasignar; Si CV<0: limitar horas, revisar tarifa o scope.
A20: 4 | D20: =WBS!Q5 -> 560 | E20: =WBS!R5 -> 560 | F20: =WBS!S5 -> 600 | G20: =E20-D20 -> 0 | H20: =E20-F20 -> -40 | I20: Si SV<0: dividir en sub-tareas o reasignar; Si CV<0: limitar horas, revisar tarifa o scope.
A21: 5 | D21: =WBS!Q6 -> 336 | E21: =WBS!R6 -> 336 | F21: =WBS!S6 -> 294 | G21: =E21-D21 -> 0 | H21: =E21-F21 -> 42 | I21: Si SV<0: dividir en sub-tareas o reasignar; Si CV<0: limitar horas, revisar tarifa o scope.
A22: 6 | D22: =WBS!Q7 -> 336 | E22: =WBS!R7 -> 336 | F22: =WBS!S7 -> 378 | G22: =E22-D22 -> 0 | H22: =E22-F22 -> -42 | I22: Si SV<0: dividir en sub-tareas o reasignar; Si CV<0: limitar horas, revisar tarifa o scope.
A23: 7 | D23: =WBS!Q8 -> 640 | E23: 640 | F23: =WBS!S8 -> 530 | G23: =E23-D23 -> 0 | H23: =E23-F23 -> 110 | I23: Si SV<0: dividir en sub-tareas o reasignar; Si CV<0: limitar horas, revisar tarifa o scope.
A24: 8 | D24: =WBS!Q9 -> 160 | E24: =WBS!R9 -> 160 | F24: =WBS!S9 -> 200 | G24: =E24-D24 -> 0 | H24: =E24-F24 -> -40 | I24: Si SV<0: dividir en sub-tareas o reasignar; Si CV<0: limitar horas, revisar tarifa o scope.
A25: 9 | D25: =WBS!Q10 -> 720 | E25: =WBS!R10 -> 720 | F25: =WBS!S10 -> 360 | G25: =E25-D25 -> 0 | H25: =E25-F25 -> 360 | I25: Si SV<0: dividir en sub-tareas o reasignar; Si CV<0: limitar horas, revisar tarifa o scope.
A26: 10 | D26: =WBS!Q11 -> 810 | E26: =WBS!R11 -> 810 | F26: =WBS!S11 -> 450 | G26: =E26-D26 -> 0 | H26: =E26-F26 -> 360 | I26: Si SV<0: dividir en sub-tareas o reasignar; Si CV<0: limitar horas, revisar tarifa o scope.
A27: 11 | D27: =WBS!Q12 -> 480 | E27: =WBS!R12 -> 480 | F27: =WBS!S12 -> 240 | G27: =E27-D27 -> 0 | H27: =E27-F27 -> 240 | I27: Si SV<0: dividir en sub-tareas o reasignar; Si CV<0: limitar horas, revisar tarifa o scope.
A28: 12 | D28: =WBS!Q13 -> 240 | E28: =WBS!R13 -> 240 | F28: =WBS!S13 -> 0 | G28: =E28-D28 -> 0 | H28: =E28-F28 -> 240 | I28: Si SV<0: dividir en sub-tareas o reasignar; Si CV<0: limitar horas, revisar tarifa o scope.
D29: =WBS!Q14 -> 520 | E29: =WBS!R14 -> 520 | F29: =WBS!S14 -> 560 | G29: =E29-D29 -> 0 | H29: =E29-F29 -> -40 | I29: Si SV<0: dividir en sub-tareas o reasignar; Si CV<0: limitar horas, revisar tarifa o scope.
D30: =WBS!Q15 -> 0 | E30: =WBS!R15 -> 240 | F30: 240 | G30: =E30-D30 -> 240 | H30: =E30-F30 -> 0 | I30: Si SV<0: dividir en sub-tareas o reasignar; Si CV<0: limitar horas, revisar tarifa o scope.
D31: =WBS!Q16 -> 0 | E31: =WBS!R16 -> 0 | F31: =WBS!S16 -> 360 | G31: =E31-D31 -> 0 | H31: =E31-F31 -> -360 | I31: Si SV<0: dividir en sub-tareas o reasignar; Si CV<0: limitar horas, revisar tarifa o scope.
D32: =WBS!Q17 -> 0 | E32: =WBS!R17 -> 64 | F32: =WBS!S17 -> 320 | G32: =E32-D32 -> 64 | H32: =E32-F32 -> -256 | I32: Si SV<0: dividir en sub-tareas o reasignar; Si CV<0: limitar horas, revisar tarifa o scope.
D33: =WBS!Q18 -> 0 | E33: =WBS!R18 -> 0 | F33: =WBS!S18 -> 240 | G33: =E33-D33 -> 0 | H33: =E33-F33 -> -240 | I33: Si SV<0: dividir en sub-tareas o reasignar; Si CV<0: limitar horas, revisar tarifa o scope.
D34: =WBS!Q19 -> 0 | E34: =WBS!R19 -> 0 | F34: =WBS!S19 -> 210 | G34: =E34-D34 -> 0 | H34: =E34-F34 -> -210 | I34: Si SV<0: dividir en sub-tareas o reasignar; Si CV<0: limitar horas, revisar tarifa o scope.
D35: =WBS!Q20 -> 0 | E35: =WBS!R20 -> 0 | F35: =WBS!S20 -> 390 | G35: =E35-D35 -> 0 | H35: =E35-F35 -> -390 | I35: Si SV<0: dividir en sub-tareas o reasignar; Si CV<0: limitar horas, revisar tarifa o scope.
D36: =WBS!Q21 -> 0 | E36: =WBS!R21 -> 0 | F36: =WBS!S21 -> 200 | G36: =E36-D36 -> 0 | H36: =E36-F36 -> -200 | I36: Si SV<0: dividir en sub-tareas o reasignar; Si CV<0: limitar horas, revisar tarifa o scope.
D37: =WBS!Q22 -> 0 | E37: =WBS!R22 -> 0 | F37: =WBS!S22 -> 0 | G37: =E37-D37 -> 0 | H37: =E37-F37 -> 0 | I37: Si SV<0: dividir en sub-tareas o reasignar; Si CV<0: limitar horas, revisar tarifa o scope.
D38: =WBS!Q23 | E38: =WBS!R23 -> 0 | F38: =WBS!S23 -> 0 | G38: =E38-D38 -> 0 | H38: =E38-F38 -> 0 | I38: Si SV<0: dividir en sub-tareas o reasignar; Si CV<0: limitar horas, revisar tarifa o scope.
D39: =WBS!Q24 | E39: =WBS!R24 -> 0 | F39: =WBS!S24 -> 0 | G39: =E39-D39 -> 0 | H39: =E39-F39 -> 0 | I39: Si SV<0: dividir en sub-tareas o reasignar; Si CV<0: limitar horas, revisar tarifa o scope.
D40: =WBS!Q25 | E40: =WBS!R25 -> 0 | F40: =WBS!S25 -> 0 | G40: =E40-D40 -> 0 | H40: =E40-F40 -> 0 | I40: Si SV<0: dividir en sub-tareas o reasignar; Si CV<0: limitar horas, revisar tarifa o scope.
D41: =WBS!Q26 | E41: =WBS!R26 -> 0 | F41: =WBS!S26 -> 0 | G41: =E41-D41 -> 0 | H41: =E41-F41 -> 0 | I41: Si SV<0: dividir en sub-tareas o reasignar; Si CV<0: limitar horas, revisar tarifa o scope.
D42: =WBS!Q27 | E42: =WBS!R27 -> 0 | F42: =WBS!S27 -> 0 | G42: =E42-D42 -> 0 | H42: =E42-F42 -> 0 | I42: Si SV<0: dividir en sub-tareas o reasignar; Si CV<0: limitar horas, revisar tarifa o scope.
... D55: =WBS!Q40 | E55: =WBS!R40 -> 0 | F55: =WBS!S40 -> 0 | G55: =E55-D55 -> 0 | H55: =E55-F55 -> 0 | I55: Si SV<0: dividir en sub-tareas o reasignar; Si CV<0: limitar horas, revisar tarifa o scope.

Sheet Interpretacion
B3: curva S (PV vs EV vs AC)
B5: PV (azul): lo que deberíamos llevar según el plan.
B6: EV (rojo): lo que realmente logramos (valor ganado).
B7: AC (verde): lo que realmente gastamos (costo).
B9: Intepretacion
B10: EV vs PV: si EV va debajo de PV, vamos atrasados; si EV alcanza o supera PV, vamos al día o adelantados.
B11: EV vs AC: si EV va debajo de AC, estamos gastando más de lo que estamos logrando (riesgo de sobrecosto).
B12: Pendientes: subidas grandes = cerramos varias tareas; tramos planos = nos frenamos.
B14: Qué dice la gráfica: al final se ve PV > AC > EV ⇒ atraso (EV < PV) y gasto algo alto para lo que hemos logrado (EV < AC).
B18: burnup (EV vs PV + BAC)
B20: EV (azul) subiendo con el trabajo real.
B21: PV (rojo) mostrando el ritmo planeado.
... B36: Para el próximo sprint: planear entregas pequeñas y frecuentes para que EV suba parejo y se acerque a PV.
